Traceback (most recent call last):
  File "./api_server.py", line 62, in <module>
    mysqlId=os.environ['MYSQL_ID']
  File "/usr/lib/python2.7/UserDict.py", line 40, in __getitem__
    raise KeyError(key)
KeyError: 'MYSQL_ID'
/home/ubuntu/.local/lib/python2.7/site-packages/sqlalchemy/dialects/mysql/base.py:2497: Warning: '@@tx_isolation' is deprecated and will be removed in a future release. Please use '@@transaction_isolation' instead
  cursor.execute('SELECT @@tx_isolation')
 * Serving Flask app "api_server" (lazy loading)
 * Environment: production
   WARNING: Do not use the development server in a production environment.
   Use a production WSGI server instead.
 * Debug mode: on
/home/ubuntu/.local/lib/python2.7/site-packages/sqlalchemy/dialects/mysql/base.py:2497: Warning: '@@tx_isolation' is deprecated and will be removed in a future release. Please use '@@transaction_isolation' instead
  cursor.execute('SELECT @@tx_isolation')
Traceback (most recent call last):
  File "/home/ubuntu/.local/lib/python2.7/site-packages/flask/app.py", line 2301, in __call__
    return self.wsgi_app(environ, start_response)
  File "/home/ubuntu/.local/lib/python2.7/site-packages/flask/app.py", line 2287, in wsgi_app
    response = self.handle_exception(e)
  File "/home/ubuntu/.local/lib/python2.7/site-packages/flask/app.py", line 1733, in handle_exception
    reraise(exc_type, exc_value, tb)
  File "/home/ubuntu/.local/lib/python2.7/site-packages/flask/app.py", line 2284, in wsgi_app
    response = self.full_dispatch_request()
  File "/home/ubuntu/.local/lib/python2.7/site-packages/flask/app.py", line 1807, in full_dispatch_request
    rv = self.handle_user_exception(e)
  File "/home/ubuntu/.local/lib/python2.7/site-packages/flask/app.py", line 1710, in handle_user_exception
    reraise(exc_type, exc_value, tb)
  File "/home/ubuntu/.local/lib/python2.7/site-packages/flask/app.py", line 1805, in full_dispatch_request
    rv = self.dispatch_request()
  File "/home/ubuntu/.local/lib/python2.7/site-packages/flask/app.py", line 1791, in dispatch_request
    return self.view_functions[rule.endpoint](**req.view_args)
  File "/home/ubuntu/api_server/api_server.py", line 106, in get_tasks
    PPTable = getPollsProspect()
  File "/home/ubuntu/.local/lib/python2.7/site-packages/statsd/client.py", line 37, in _wrapped
    return_value = f(*args, **kwargs)
  File "/home/ubuntu/api_server/api_server.py", line 83, in getPollsProspect
    results = q.execute()
  File "/home/ubuntu/.local/lib/python2.7/site-packages/sqlalchemy/sql/base.py", line 386, in execute
    return e._execute_clauseelement(self, multiparams, params)
  File "/home/ubuntu/.local/lib/python2.7/site-packages/sqlalchemy/engine/base.py", line 1998, in _execute_clauseelement
    return connection._execute_clauseelement(elem, multiparams, params)
  File "/home/ubuntu/.local/lib/python2.7/site-packages/sqlalchemy/engine/base.py", line 1010, in _execute_clauseelement
    compiled_sql, distilled_params
  File "/home/ubuntu/.local/lib/python2.7/site-packages/sqlalchemy/engine/base.py", line 1146, in _execute_context
    context)
  File "/home/ubuntu/.local/lib/python2.7/site-packages/sqlalchemy/engine/base.py", line 1341, in _handle_dbapi_exception
    exc_info
  File "/home/ubuntu/.local/lib/python2.7/site-packages/sqlalchemy/util/compat.py", line 200, in raise_from_cause
    reraise(type(exception), exception, tb=exc_tb)
  File "/home/ubuntu/.local/lib/python2.7/site-packages/sqlalchemy/engine/base.py", line 1139, in _execute_context
    context)
  File "/home/ubuntu/.local/lib/python2.7/site-packages/sqlalchemy/engine/default.py", line 450, in do_execute
    cursor.execute(statement, parameters)
  File "/home/ubuntu/.local/lib/python2.7/site-packages/MySQLdb/cursors.py", line 205, in execute
    self.errorhandler(self, exc, value)
  File "/home/ubuntu/.local/lib/python2.7/site-packages/MySQLdb/connections.py", line 36, in defaulterrorhandler
    raise errorclass, errorvalue
OperationalError: (_mysql_exceptions.OperationalError) (2013, 'Lost connection to MySQL server during query') [SQL: u'SELECT polls_prospect.id, polls_prospect.firstname, polls_prospect.lastname, polls_prospect.email \nFROM polls_prospect']
Traceback (most recent call last):
  File "/home/ubuntu/.local/lib/python2.7/site-packages/flask/app.py", line 2301, in __call__
    return self.wsgi_app(environ, start_response)
  File "/home/ubuntu/.local/lib/python2.7/site-packages/flask/app.py", line 2287, in wsgi_app
    response = self.handle_exception(e)
  File "/home/ubuntu/.local/lib/python2.7/site-packages/flask/app.py", line 1733, in handle_exception
    reraise(exc_type, exc_value, tb)
  File "/home/ubuntu/.local/lib/python2.7/site-packages/flask/app.py", line 2284, in wsgi_app
    response = self.full_dispatch_request()
  File "/home/ubuntu/.local/lib/python2.7/site-packages/flask/app.py", line 1807, in full_dispatch_request
    rv = self.handle_user_exception(e)
  File "/home/ubuntu/.local/lib/python2.7/site-packages/flask/app.py", line 1710, in handle_user_exception
    reraise(exc_type, exc_value, tb)
  File "/home/ubuntu/.local/lib/python2.7/site-packages/flask/app.py", line 1805, in full_dispatch_request
    rv = self.dispatch_request()
  File "/home/ubuntu/.local/lib/python2.7/site-packages/flask/app.py", line 1791, in dispatch_request
    return self.view_functions[rule.endpoint](**req.view_args)
  File "/home/ubuntu/api_server/api_server.py", line 106, in get_tasks
    PPTable = getPollsProspect()
  File "/home/ubuntu/.local/lib/python2.7/site-packages/statsd/client.py", line 37, in _wrapped
    return_value = f(*args, **kwargs)
  File "/home/ubuntu/api_server/api_server.py", line 83, in getPollsProspect
    results = q.execute()
  File "/home/ubuntu/.local/lib/python2.7/site-packages/sqlalchemy/sql/base.py", line 386, in execute
    return e._execute_clauseelement(self, multiparams, params)
  File "/home/ubuntu/.local/lib/python2.7/site-packages/sqlalchemy/engine/base.py", line 1998, in _execute_clauseelement
    return connection._execute_clauseelement(elem, multiparams, params)
  File "/home/ubuntu/.local/lib/python2.7/site-packages/sqlalchemy/engine/base.py", line 1010, in _execute_clauseelement
    compiled_sql, distilled_params
  File "/home/ubuntu/.local/lib/python2.7/site-packages/sqlalchemy/engine/base.py", line 1146, in _execute_context
    context)
  File "/home/ubuntu/.local/lib/python2.7/site-packages/sqlalchemy/engine/base.py", line 1341, in _handle_dbapi_exception
    exc_info
  File "/home/ubuntu/.local/lib/python2.7/site-packages/sqlalchemy/util/compat.py", line 200, in raise_from_cause
    reraise(type(exception), exception, tb=exc_tb)
  File "/home/ubuntu/.local/lib/python2.7/site-packages/sqlalchemy/engine/base.py", line 1139, in _execute_context
    context)
  File "/home/ubuntu/.local/lib/python2.7/site-packages/sqlalchemy/engine/default.py", line 450, in do_execute
    cursor.execute(statement, parameters)
  File "/home/ubuntu/.local/lib/python2.7/site-packages/MySQLdb/cursors.py", line 205, in execute
    self.errorhandler(self, exc, value)
  File "/home/ubuntu/.local/lib/python2.7/site-packages/MySQLdb/connections.py", line 36, in defaulterrorhandler
    raise errorclass, errorvalue
OperationalError: (_mysql_exceptions.OperationalError) (2013, 'Lost connection to MySQL server during query') [SQL: u'SELECT polls_prospect.id, polls_prospect.firstname, polls_prospect.lastname, polls_prospect.email \nFROM polls_prospect']
api_server.py: 3: api_server.py: import: not found
api_server.py: 4: api_server.py: import: not found
from: can't read /var/mail/sqlalchemy.ext.declarative
from: can't read /var/mail/sqlalchemy
from: can't read /var/mail/sqlalchemy.orm
from: can't read /var/mail/sqlalchemy
from: can't read /var/mail/statsd
from: can't read /var/mail/logging.config
from: can't read /var/mail/logging.handlers
api_server.py: 14: api_server.py: Syntax error: word unexpected (expecting ")")
/home/ubuntu/.local/lib/python2.7/site-packages/sqlalchemy/dialects/mysql/base.py:2497: Warning: '@@tx_isolation' is deprecated and will be removed in a future release. Please use '@@transaction_isolation' instead
  cursor.execute('SELECT @@tx_isolation')
 * Serving Flask app "api_server" (lazy loading)
 * Environment: production
   WARNING: Do not use the development server in a production environment.
   Use a production WSGI server instead.
 * Debug mode: on
/home/ubuntu/.local/lib/python2.7/site-packages/sqlalchemy/dialects/mysql/base.py:2497: Warning: '@@tx_isolation' is deprecated and will be removed in a future release. Please use '@@transaction_isolation' instead
  cursor.execute('SELECT @@tx_isolation')
/home/ubuntu/.local/lib/python2.7/site-packages/sqlalchemy/dialects/mysql/base.py:2497: Warning: '@@tx_isolation' is deprecated and will be removed in a future release. Please use '@@transaction_isolation' instead
  cursor.execute('SELECT @@tx_isolation')
 * Serving Flask app "api_server" (lazy loading)
 * Environment: production
   WARNING: Do not use the development server in a production environment.
   Use a production WSGI server instead.
 * Debug mode: on
Traceback (most recent call last):
  File "api_server.py", line 117, in <module>
    app.run(host='0.0.0.0', port=5000)
  File "/home/ubuntu/.local/lib/python2.7/site-packages/flask/app.py", line 941, in run
    run_simple(host, port, self, **options)
  File "/home/ubuntu/.local/lib/python2.7/site-packages/werkzeug/serving.py", line 780, in run_simple
    s.bind((hostname, port))
  File "/usr/lib/python2.7/socket.py", line 228, in meth
    return getattr(self._sock,name)(*args)
socket.error: [Errno 98] Address already in use
/home/ubuntu/.local/lib/python2.7/site-packages/sqlalchemy/dialects/mysql/base.py:2497: Warning: '@@tx_isolation' is deprecated and will be removed in a future release. Please use '@@transaction_isolation' instead
  cursor.execute('SELECT @@tx_isolation')
 * Serving Flask app "api_server" (lazy loading)
 * Environment: production
   WARNING: Do not use the development server in a production environment.
   Use a production WSGI server instead.
 * Debug mode: on
/home/ubuntu/.local/lib/python2.7/site-packages/sqlalchemy/dialects/mysql/base.py:2497: Warning: '@@tx_isolation' is deprecated and will be removed in a future release. Please use '@@transaction_isolation' instead
  cursor.execute('SELECT @@tx_isolation')
Traceback (most recent call last):
  File "/home/ubuntu/.local/lib/python2.7/site-packages/flask/app.py", line 2301, in __call__
    return self.wsgi_app(environ, start_response)
  File "/home/ubuntu/.local/lib/python2.7/site-packages/flask/app.py", line 2287, in wsgi_app
    response = self.handle_exception(e)
  File "/home/ubuntu/.local/lib/python2.7/site-packages/flask/app.py", line 1733, in handle_exception
    reraise(exc_type, exc_value, tb)
  File "/home/ubuntu/.local/lib/python2.7/site-packages/flask/app.py", line 2284, in wsgi_app
    response = self.full_dispatch_request()
  File "/home/ubuntu/.local/lib/python2.7/site-packages/flask/app.py", line 1807, in full_dispatch_request
    rv = self.handle_user_exception(e)
  File "/home/ubuntu/.local/lib/python2.7/site-packages/flask/app.py", line 1710, in handle_user_exception
    reraise(exc_type, exc_value, tb)
  File "/home/ubuntu/.local/lib/python2.7/site-packages/flask/app.py", line 1805, in full_dispatch_request
    rv = self.dispatch_request()
  File "/home/ubuntu/.local/lib/python2.7/site-packages/flask/app.py", line 1791, in dispatch_request
    return self.view_functions[rule.endpoint](**req.view_args)
  File "/home/ubuntu/api_server/api_server.py", line 106, in get_tasks
    PPTable = getPollsProspect()
  File "/home/ubuntu/.local/lib/python2.7/site-packages/statsd/client.py", line 37, in _wrapped
    return_value = f(*args, **kwargs)
  File "/home/ubuntu/api_server/api_server.py", line 83, in getPollsProspect
    results = q.execute()
  File "/home/ubuntu/.local/lib/python2.7/site-packages/sqlalchemy/sql/base.py", line 386, in execute
    return e._execute_clauseelement(self, multiparams, params)
  File "/home/ubuntu/.local/lib/python2.7/site-packages/sqlalchemy/engine/base.py", line 1998, in _execute_clauseelement
    return connection._execute_clauseelement(elem, multiparams, params)
  File "/home/ubuntu/.local/lib/python2.7/site-packages/sqlalchemy/engine/base.py", line 1010, in _execute_clauseelement
    compiled_sql, distilled_params
  File "/home/ubuntu/.local/lib/python2.7/site-packages/sqlalchemy/engine/base.py", line 1146, in _execute_context
    context)
  File "/home/ubuntu/.local/lib/python2.7/site-packages/sqlalchemy/engine/base.py", line 1341, in _handle_dbapi_exception
    exc_info
  File "/home/ubuntu/.local/lib/python2.7/site-packages/sqlalchemy/util/compat.py", line 200, in raise_from_cause
    reraise(type(exception), exception, tb=exc_tb)
  File "/home/ubuntu/.local/lib/python2.7/site-packages/sqlalchemy/engine/base.py", line 1139, in _execute_context
    context)
  File "/home/ubuntu/.local/lib/python2.7/site-packages/sqlalchemy/engine/default.py", line 450, in do_execute
    cursor.execute(statement, parameters)
  File "/home/ubuntu/.local/lib/python2.7/site-packages/MySQLdb/cursors.py", line 205, in execute
    self.errorhandler(self, exc, value)
  File "/home/ubuntu/.local/lib/python2.7/site-packages/MySQLdb/connections.py", line 36, in defaulterrorhandler
    raise errorclass, errorvalue
OperationalError: (_mysql_exceptions.OperationalError) (2013, 'Lost connection to MySQL server during query') [SQL: u'SELECT polls_prospect.id, polls_prospect.firstname, polls_prospect.lastname, polls_prospect.email \nFROM polls_prospect']
Traceback (most recent call last):
  File "/home/ubuntu/.local/lib/python2.7/site-packages/flask/app.py", line 2301, in __call__
    return self.wsgi_app(environ, start_response)
  File "/home/ubuntu/.local/lib/python2.7/site-packages/flask/app.py", line 2287, in wsgi_app
    response = self.handle_exception(e)
  File "/home/ubuntu/.local/lib/python2.7/site-packages/flask/app.py", line 1733, in handle_exception
    reraise(exc_type, exc_value, tb)
  File "/home/ubuntu/.local/lib/python2.7/site-packages/flask/app.py", line 2284, in wsgi_app
    response = self.full_dispatch_request()
  File "/home/ubuntu/.local/lib/python2.7/site-packages/flask/app.py", line 1807, in full_dispatch_request
    rv = self.handle_user_exception(e)
  File "/home/ubuntu/.local/lib/python2.7/site-packages/flask/app.py", line 1710, in handle_user_exception
    reraise(exc_type, exc_value, tb)
  File "/home/ubuntu/.local/lib/python2.7/site-packages/flask/app.py", line 1805, in full_dispatch_request
    rv = self.dispatch_request()
  File "/home/ubuntu/.local/lib/python2.7/site-packages/flask/app.py", line 1791, in dispatch_request
    return self.view_functions[rule.endpoint](**req.view_args)
  File "/home/ubuntu/api_server/api_server.py", line 106, in get_tasks
    PPTable = getPollsProspect()
  File "/home/ubuntu/.local/lib/python2.7/site-packages/statsd/client.py", line 37, in _wrapped
    return_value = f(*args, **kwargs)
  File "/home/ubuntu/api_server/api_server.py", line 83, in getPollsProspect
    results = q.execute()
  File "/home/ubuntu/.local/lib/python2.7/site-packages/sqlalchemy/sql/base.py", line 386, in execute
    return e._execute_clauseelement(self, multiparams, params)
  File "/home/ubuntu/.local/lib/python2.7/site-packages/sqlalchemy/engine/base.py", line 1998, in _execute_clauseelement
    return connection._execute_clauseelement(elem, multiparams, params)
  File "/home/ubuntu/.local/lib/python2.7/site-packages/sqlalchemy/engine/base.py", line 1010, in _execute_clauseelement
    compiled_sql, distilled_params
  File "/home/ubuntu/.local/lib/python2.7/site-packages/sqlalchemy/engine/base.py", line 1146, in _execute_context
    context)
  File "/home/ubuntu/.local/lib/python2.7/site-packages/sqlalchemy/engine/base.py", line 1341, in _handle_dbapi_exception
    exc_info
  File "/home/ubuntu/.local/lib/python2.7/site-packages/sqlalchemy/util/compat.py", line 200, in raise_from_cause
    reraise(type(exception), exception, tb=exc_tb)
  File "/home/ubuntu/.local/lib/python2.7/site-packages/sqlalchemy/engine/base.py", line 1139, in _execute_context
    context)
  File "/home/ubuntu/.local/lib/python2.7/site-packages/sqlalchemy/engine/default.py", line 450, in do_execute
    cursor.execute(statement, parameters)
  File "/home/ubuntu/.local/lib/python2.7/site-packages/MySQLdb/cursors.py", line 205, in execute
    self.errorhandler(self, exc, value)
  File "/home/ubuntu/.local/lib/python2.7/site-packages/MySQLdb/connections.py", line 36, in defaulterrorhandler
    raise errorclass, errorvalue
OperationalError: (_mysql_exceptions.OperationalError) (2006, 'MySQL server has gone away') [SQL: u'SELECT polls_prospect.id, polls_prospect.firstname, polls_prospect.lastname, polls_prospect.email \nFROM polls_prospect']
Traceback (most recent call last):
  File "/home/ubuntu/.local/lib/python2.7/site-packages/flask/app.py", line 2301, in __call__
    return self.wsgi_app(environ, start_response)
  File "/home/ubuntu/.local/lib/python2.7/site-packages/flask/app.py", line 2287, in wsgi_app
    response = self.handle_exception(e)
  File "/home/ubuntu/.local/lib/python2.7/site-packages/flask/app.py", line 1733, in handle_exception
    reraise(exc_type, exc_value, tb)
  File "/home/ubuntu/.local/lib/python2.7/site-packages/flask/app.py", line 2284, in wsgi_app
    response = self.full_dispatch_request()
  File "/home/ubuntu/.local/lib/python2.7/site-packages/flask/app.py", line 1807, in full_dispatch_request
    rv = self.handle_user_exception(e)
  File "/home/ubuntu/.local/lib/python2.7/site-packages/flask/app.py", line 1710, in handle_user_exception
    reraise(exc_type, exc_value, tb)
  File "/home/ubuntu/.local/lib/python2.7/site-packages/flask/app.py", line 1805, in full_dispatch_request
    rv = self.dispatch_request()
  File "/home/ubuntu/.local/lib/python2.7/site-packages/flask/app.py", line 1791, in dispatch_request
    return self.view_functions[rule.endpoint](**req.view_args)
  File "/home/ubuntu/api_server/api_server.py", line 106, in get_tasks
    PPTable = getPollsProspect()
  File "/home/ubuntu/.local/lib/python2.7/site-packages/statsd/client.py", line 37, in _wrapped
    return_value = f(*args, **kwargs)
  File "/home/ubuntu/api_server/api_server.py", line 83, in getPollsProspect
    results = q.execute()
  File "/home/ubuntu/.local/lib/python2.7/site-packages/sqlalchemy/sql/base.py", line 386, in execute
    return e._execute_clauseelement(self, multiparams, params)
  File "/home/ubuntu/.local/lib/python2.7/site-packages/sqlalchemy/engine/base.py", line 1998, in _execute_clauseelement
    return connection._execute_clauseelement(elem, multiparams, params)
  File "/home/ubuntu/.local/lib/python2.7/site-packages/sqlalchemy/engine/base.py", line 1010, in _execute_clauseelement
    compiled_sql, distilled_params
  File "/home/ubuntu/.local/lib/python2.7/site-packages/sqlalchemy/engine/base.py", line 1146, in _execute_context
    context)
  File "/home/ubuntu/.local/lib/python2.7/site-packages/sqlalchemy/engine/base.py", line 1341, in _handle_dbapi_exception
    exc_info
  File "/home/ubuntu/.local/lib/python2.7/site-packages/sqlalchemy/util/compat.py", line 200, in raise_from_cause
    reraise(type(exception), exception, tb=exc_tb)
  File "/home/ubuntu/.local/lib/python2.7/site-packages/sqlalchemy/engine/base.py", line 1139, in _execute_context
    context)
  File "/home/ubuntu/.local/lib/python2.7/site-packages/sqlalchemy/engine/default.py", line 450, in do_execute
    cursor.execute(statement, parameters)
  File "/home/ubuntu/.local/lib/python2.7/site-packages/MySQLdb/cursors.py", line 205, in execute
    self.errorhandler(self, exc, value)
  File "/home/ubuntu/.local/lib/python2.7/site-packages/MySQLdb/connections.py", line 36, in defaulterrorhandler
    raise errorclass, errorvalue
OperationalError: (_mysql_exceptions.OperationalError) (2013, 'Lost connection to MySQL server during query') [SQL: u'SELECT polls_prospect.id, polls_prospect.firstname, polls_prospect.lastname, polls_prospect.email \nFROM polls_prospect']
Traceback (most recent call last):
  File "/usr/lib/python2.7/SocketServer.py", line 596, in process_request_thread
    self.finish_request(request, client_address)
  File "/usr/lib/python2.7/SocketServer.py", line 331, in finish_request
    self.RequestHandlerClass(request, client_address, self)
  File "/usr/lib/python2.7/SocketServer.py", line 652, in __init__
    self.handle()
  File "/home/ubuntu/.local/lib/python2.7/site-packages/werkzeug/serving.py", line 290, in handle
    rv = BaseHTTPRequestHandler.handle(self)
  File "/usr/lib/python2.7/BaseHTTPServer.py", line 340, in handle
    self.handle_one_request()
  File "/home/ubuntu/.local/lib/python2.7/site-packages/werkzeug/serving.py", line 321, in handle_one_request
    self.raw_requestline = self.rfile.readline()
IOError: [Errno 104] Connection reset by peer
Traceback (most recent call last):
  File "/home/ubuntu/.local/lib/python2.7/site-packages/flask/app.py", line 2301, in __call__
    return self.wsgi_app(environ, start_response)
  File "/home/ubuntu/.local/lib/python2.7/site-packages/flask/app.py", line 2287, in wsgi_app
    response = self.handle_exception(e)
  File "/home/ubuntu/.local/lib/python2.7/site-packages/flask/app.py", line 1733, in handle_exception
    reraise(exc_type, exc_value, tb)
  File "/home/ubuntu/.local/lib/python2.7/site-packages/flask/app.py", line 2284, in wsgi_app
    response = self.full_dispatch_request()
  File "/home/ubuntu/.local/lib/python2.7/site-packages/flask/app.py", line 1807, in full_dispatch_request
    rv = self.handle_user_exception(e)
  File "/home/ubuntu/.local/lib/python2.7/site-packages/flask/app.py", line 1710, in handle_user_exception
    reraise(exc_type, exc_value, tb)
  File "/home/ubuntu/.local/lib/python2.7/site-packages/flask/app.py", line 1805, in full_dispatch_request
    rv = self.dispatch_request()
  File "/home/ubuntu/.local/lib/python2.7/site-packages/flask/app.py", line 1791, in dispatch_request
    return self.view_functions[rule.endpoint](**req.view_args)
  File "/home/ubuntu/api_server/api_server.py", line 106, in get_tasks
    PPTable = getPollsProspect()
  File "/home/ubuntu/.local/lib/python2.7/site-packages/statsd/client.py", line 37, in _wrapped
    return_value = f(*args, **kwargs)
  File "/home/ubuntu/api_server/api_server.py", line 83, in getPollsProspect
    results = q.execute()
  File "/home/ubuntu/.local/lib/python2.7/site-packages/sqlalchemy/sql/base.py", line 386, in execute
    return e._execute_clauseelement(self, multiparams, params)
  File "/home/ubuntu/.local/lib/python2.7/site-packages/sqlalchemy/engine/base.py", line 1998, in _execute_clauseelement
    return connection._execute_clauseelement(elem, multiparams, params)
  File "/home/ubuntu/.local/lib/python2.7/site-packages/sqlalchemy/engine/base.py", line 1010, in _execute_clauseelement
    compiled_sql, distilled_params
  File "/home/ubuntu/.local/lib/python2.7/site-packages/sqlalchemy/engine/base.py", line 1146, in _execute_context
    context)
  File "/home/ubuntu/.local/lib/python2.7/site-packages/sqlalchemy/engine/base.py", line 1341, in _handle_dbapi_exception
    exc_info
  File "/home/ubuntu/.local/lib/python2.7/site-packages/sqlalchemy/util/compat.py", line 200, in raise_from_cause
    reraise(type(exception), exception, tb=exc_tb)
  File "/home/ubuntu/.local/lib/python2.7/site-packages/sqlalchemy/engine/base.py", line 1139, in _execute_context
    context)
  File "/home/ubuntu/.local/lib/python2.7/site-packages/sqlalchemy/engine/default.py", line 450, in do_execute
    cursor.execute(statement, parameters)
  File "/home/ubuntu/.local/lib/python2.7/site-packages/MySQLdb/cursors.py", line 205, in execute
    self.errorhandler(self, exc, value)
  File "/home/ubuntu/.local/lib/python2.7/site-packages/MySQLdb/connections.py", line 36, in defaulterrorhandler
    raise errorclass, errorvalue
OperationalError: (_mysql_exceptions.OperationalError) (2013, 'Lost connection to MySQL server during query') [SQL: u'SELECT polls_prospect.id, polls_prospect.firstname, polls_prospect.lastname, polls_prospect.email \nFROM polls_prospect']
Traceback (most recent call last):
  File "/usr/lib/python2.7/SocketServer.py", line 596, in process_request_thread
    self.finish_request(request, client_address)
  File "/usr/lib/python2.7/SocketServer.py", line 331, in finish_request
    self.RequestHandlerClass(request, client_address, self)
  File "/usr/lib/python2.7/SocketServer.py", line 652, in __init__
    self.handle()
  File "/home/ubuntu/.local/lib/python2.7/site-packages/werkzeug/serving.py", line 290, in handle
    rv = BaseHTTPRequestHandler.handle(self)
  File "/usr/lib/python2.7/BaseHTTPServer.py", line 340, in handle
    self.handle_one_request()
  File "/home/ubuntu/.local/lib/python2.7/site-packages/werkzeug/serving.py", line 321, in handle_one_request
    self.raw_requestline = self.rfile.readline()
IOError: [Errno 104] Connection reset by peer
Traceback (most recent call last):
  File "/usr/lib/python2.7/SocketServer.py", line 596, in process_request_thread
    self.finish_request(request, client_address)
  File "/usr/lib/python2.7/SocketServer.py", line 331, in finish_request
    self.RequestHandlerClass(request, client_address, self)
  File "/usr/lib/python2.7/SocketServer.py", line 652, in __init__
    self.handle()
  File "/home/ubuntu/.local/lib/python2.7/site-packages/werkzeug/serving.py", line 290, in handle
    rv = BaseHTTPRequestHandler.handle(self)
  File "/usr/lib/python2.7/BaseHTTPServer.py", line 340, in handle
    self.handle_one_request()
  File "/home/ubuntu/.local/lib/python2.7/site-packages/werkzeug/serving.py", line 321, in handle_one_request
    self.raw_requestline = self.rfile.readline()
IOError: [Errno 104] Connection reset by peer
Traceback (most recent call last):
  File "/usr/lib/python2.7/SocketServer.py", line 596, in process_request_thread
    self.finish_request(request, client_address)
  File "/usr/lib/python2.7/SocketServer.py", line 331, in finish_request
    self.RequestHandlerClass(request, client_address, self)
  File "/usr/lib/python2.7/SocketServer.py", line 652, in __init__
    self.handle()
  File "/home/ubuntu/.local/lib/python2.7/site-packages/werkzeug/serving.py", line 290, in handle
    rv = BaseHTTPRequestHandler.handle(self)
  File "/usr/lib/python2.7/BaseHTTPServer.py", line 340, in handle
    self.handle_one_request()
  File "/home/ubuntu/.local/lib/python2.7/site-packages/werkzeug/serving.py", line 321, in handle_one_request
    self.raw_requestline = self.rfile.readline()
IOError: [Errno 104] Connection reset by peer
----------------------------------------
Exception happened during processing of request from ('185.156.177.2', 42461)
----------------------------------------
----------------------------------------
Exception happened during processing of request from ('185.156.177.2', 33338)
----------------------------------------
----------------------------------------
Exception happened during processing of request from ('185.156.177.13', 15623)
----------------------------------------
----------------------------------------
Exception happened during processing of request from ('185.92.73.85', 35121)
----------------------------------------
/home/ubuntu/.local/lib/python2.7/site-packages/sqlalchemy/dialects/mysql/base.py:2497: Warning: '@@tx_isolation' is deprecated and will be removed in a future release. Please use '@@transaction_isolation' instead
  cursor.execute('SELECT @@tx_isolation')
 * Serving Flask app "api_server" (lazy loading)
 * Environment: production
   WARNING: Do not use the development server in a production environment.
   Use a production WSGI server instead.
 * Debug mode: on
/home/ubuntu/.local/lib/python2.7/site-packages/sqlalchemy/dialects/mysql/base.py:2497: Warning: '@@tx_isolation' is deprecated and will be removed in a future release. Please use '@@transaction_isolation' instead
  cursor.execute('SELECT @@tx_isolation')
Traceback (most recent call last):
  File "/home/ubuntu/.local/lib/python2.7/site-packages/flask/app.py", line 2301, in __call__
    return self.wsgi_app(environ, start_response)
  File "/home/ubuntu/.local/lib/python2.7/site-packages/flask/app.py", line 2287, in wsgi_app
    response = self.handle_exception(e)
  File "/home/ubuntu/.local/lib/python2.7/site-packages/flask/app.py", line 1733, in handle_exception
    reraise(exc_type, exc_value, tb)
  File "/home/ubuntu/.local/lib/python2.7/site-packages/flask/app.py", line 2284, in wsgi_app
    response = self.full_dispatch_request()
  File "/home/ubuntu/.local/lib/python2.7/site-packages/flask/app.py", line 1807, in full_dispatch_request
    rv = self.handle_user_exception(e)
  File "/home/ubuntu/.local/lib/python2.7/site-packages/flask/app.py", line 1710, in handle_user_exception
    reraise(exc_type, exc_value, tb)
  File "/home/ubuntu/.local/lib/python2.7/site-packages/flask/app.py", line 1805, in full_dispatch_request
    rv = self.dispatch_request()
  File "/home/ubuntu/.local/lib/python2.7/site-packages/flask/app.py", line 1791, in dispatch_request
    return self.view_functions[rule.endpoint](**req.view_args)
  File "/home/ubuntu/api_server/api_server.py", line 106, in get_tasks
    PPTable = getPollsProspect()
  File "/home/ubuntu/.local/lib/python2.7/site-packages/statsd/client.py", line 37, in _wrapped
    return_value = f(*args, **kwargs)
  File "/home/ubuntu/api_server/api_server.py", line 83, in getPollsProspect
    results = q.execute()
  File "/home/ubuntu/.local/lib/python2.7/site-packages/sqlalchemy/sql/base.py", line 386, in execute
    return e._execute_clauseelement(self, multiparams, params)
  File "/home/ubuntu/.local/lib/python2.7/site-packages/sqlalchemy/engine/base.py", line 1998, in _execute_clauseelement
    return connection._execute_clauseelement(elem, multiparams, params)
  File "/home/ubuntu/.local/lib/python2.7/site-packages/sqlalchemy/engine/base.py", line 1010, in _execute_clauseelement
    compiled_sql, distilled_params
  File "/home/ubuntu/.local/lib/python2.7/site-packages/sqlalchemy/engine/base.py", line 1146, in _execute_context
    context)
  File "/home/ubuntu/.local/lib/python2.7/site-packages/sqlalchemy/engine/base.py", line 1341, in _handle_dbapi_exception
    exc_info
  File "/home/ubuntu/.local/lib/python2.7/site-packages/sqlalchemy/util/compat.py", line 200, in raise_from_cause
    reraise(type(exception), exception, tb=exc_tb)
  File "/home/ubuntu/.local/lib/python2.7/site-packages/sqlalchemy/engine/base.py", line 1139, in _execute_context
    context)
  File "/home/ubuntu/.local/lib/python2.7/site-packages/sqlalchemy/engine/default.py", line 450, in do_execute
    cursor.execute(statement, parameters)
  File "/home/ubuntu/.local/lib/python2.7/site-packages/MySQLdb/cursors.py", line 205, in execute
    self.errorhandler(self, exc, value)
  File "/home/ubuntu/.local/lib/python2.7/site-packages/MySQLdb/connections.py", line 36, in defaulterrorhandler
    raise errorclass, errorvalue
OperationalError: (_mysql_exceptions.OperationalError) (2013, 'Lost connection to MySQL server during query') [SQL: u'SELECT polls_prospect.id, polls_prospect.firstname, polls_prospect.lastname, polls_prospect.email \nFROM polls_prospect']
Traceback (most recent call last):
  File "/home/ubuntu/.local/lib/python2.7/site-packages/flask/app.py", line 2301, in __call__
    return self.wsgi_app(environ, start_response)
  File "/home/ubuntu/.local/lib/python2.7/site-packages/flask/app.py", line 2287, in wsgi_app
    response = self.handle_exception(e)
  File "/home/ubuntu/.local/lib/python2.7/site-packages/flask/app.py", line 1733, in handle_exception
    reraise(exc_type, exc_value, tb)
  File "/home/ubuntu/.local/lib/python2.7/site-packages/flask/app.py", line 2284, in wsgi_app
    response = self.full_dispatch_request()
  File "/home/ubuntu/.local/lib/python2.7/site-packages/flask/app.py", line 1807, in full_dispatch_request
    rv = self.handle_user_exception(e)
  File "/home/ubuntu/.local/lib/python2.7/site-packages/flask/app.py", line 1710, in handle_user_exception
    reraise(exc_type, exc_value, tb)
  File "/home/ubuntu/.local/lib/python2.7/site-packages/flask/app.py", line 1805, in full_dispatch_request
    rv = self.dispatch_request()
  File "/home/ubuntu/.local/lib/python2.7/site-packages/flask/app.py", line 1791, in dispatch_request
    return self.view_functions[rule.endpoint](**req.view_args)
  File "/home/ubuntu/api_server/api_server.py", line 106, in get_tasks
    PPTable = getPollsProspect()
  File "/home/ubuntu/.local/lib/python2.7/site-packages/statsd/client.py", line 37, in _wrapped
    return_value = f(*args, **kwargs)
  File "/home/ubuntu/api_server/api_server.py", line 83, in getPollsProspect
    results = q.execute()
  File "/home/ubuntu/.local/lib/python2.7/site-packages/sqlalchemy/sql/base.py", line 386, in execute
    return e._execute_clauseelement(self, multiparams, params)
  File "/home/ubuntu/.local/lib/python2.7/site-packages/sqlalchemy/engine/base.py", line 1998, in _execute_clauseelement
    return connection._execute_clauseelement(elem, multiparams, params)
  File "/home/ubuntu/.local/lib/python2.7/site-packages/sqlalchemy/engine/base.py", line 1010, in _execute_clauseelement
    compiled_sql, distilled_params
  File "/home/ubuntu/.local/lib/python2.7/site-packages/sqlalchemy/engine/base.py", line 1146, in _execute_context
    context)
  File "/home/ubuntu/.local/lib/python2.7/site-packages/sqlalchemy/engine/base.py", line 1341, in _handle_dbapi_exception
    exc_info
  File "/home/ubuntu/.local/lib/python2.7/site-packages/sqlalchemy/util/compat.py", line 200, in raise_from_cause
    reraise(type(exception), exception, tb=exc_tb)
  File "/home/ubuntu/.local/lib/python2.7/site-packages/sqlalchemy/engine/base.py", line 1139, in _execute_context
    context)
  File "/home/ubuntu/.local/lib/python2.7/site-packages/sqlalchemy/engine/default.py", line 450, in do_execute
    cursor.execute(statement, parameters)
  File "/home/ubuntu/.local/lib/python2.7/site-packages/MySQLdb/cursors.py", line 205, in execute
    self.errorhandler(self, exc, value)
  File "/home/ubuntu/.local/lib/python2.7/site-packages/MySQLdb/connections.py", line 36, in defaulterrorhandler
    raise errorclass, errorvalue
OperationalError: (_mysql_exceptions.OperationalError) (2006, 'MySQL server has gone away') [SQL: u'SELECT polls_prospect.id, polls_prospect.firstname, polls_prospect.lastname, polls_prospect.email \nFROM polls_prospect']
Traceback (most recent call last):
  File "/home/ubuntu/.local/lib/python2.7/site-packages/flask/app.py", line 2301, in __call__
    return self.wsgi_app(environ, start_response)
  File "/home/ubuntu/.local/lib/python2.7/site-packages/flask/app.py", line 2287, in wsgi_app
    response = self.handle_exception(e)
  File "/home/ubuntu/.local/lib/python2.7/site-packages/flask/app.py", line 1733, in handle_exception
    reraise(exc_type, exc_value, tb)
  File "/home/ubuntu/.local/lib/python2.7/site-packages/flask/app.py", line 2284, in wsgi_app
    response = self.full_dispatch_request()
  File "/home/ubuntu/.local/lib/python2.7/site-packages/flask/app.py", line 1807, in full_dispatch_request
    rv = self.handle_user_exception(e)
  File "/home/ubuntu/.local/lib/python2.7/site-packages/flask/app.py", line 1710, in handle_user_exception
    reraise(exc_type, exc_value, tb)
  File "/home/ubuntu/.local/lib/python2.7/site-packages/flask/app.py", line 1805, in full_dispatch_request
    rv = self.dispatch_request()
  File "/home/ubuntu/.local/lib/python2.7/site-packages/flask/app.py", line 1791, in dispatch_request
    return self.view_functions[rule.endpoint](**req.view_args)
  File "/home/ubuntu/api_server/api_server.py", line 106, in get_tasks
    PPTable = getPollsProspect()
  File "/home/ubuntu/.local/lib/python2.7/site-packages/statsd/client.py", line 37, in _wrapped
    return_value = f(*args, **kwargs)
  File "/home/ubuntu/api_server/api_server.py", line 83, in getPollsProspect
    results = q.execute()
  File "/home/ubuntu/.local/lib/python2.7/site-packages/sqlalchemy/sql/base.py", line 386, in execute
    return e._execute_clauseelement(self, multiparams, params)
  File "/home/ubuntu/.local/lib/python2.7/site-packages/sqlalchemy/engine/base.py", line 1998, in _execute_clauseelement
    return connection._execute_clauseelement(elem, multiparams, params)
  File "/home/ubuntu/.local/lib/python2.7/site-packages/sqlalchemy/engine/base.py", line 1010, in _execute_clauseelement
    compiled_sql, distilled_params
  File "/home/ubuntu/.local/lib/python2.7/site-packages/sqlalchemy/engine/base.py", line 1146, in _execute_context
    context)
  File "/home/ubuntu/.local/lib/python2.7/site-packages/sqlalchemy/engine/base.py", line 1341, in _handle_dbapi_exception
    exc_info
  File "/home/ubuntu/.local/lib/python2.7/site-packages/sqlalchemy/util/compat.py", line 200, in raise_from_cause
    reraise(type(exception), exception, tb=exc_tb)
  File "/home/ubuntu/.local/lib/python2.7/site-packages/sqlalchemy/engine/base.py", line 1139, in _execute_context
    context)
  File "/home/ubuntu/.local/lib/python2.7/site-packages/sqlalchemy/engine/default.py", line 450, in do_execute
    cursor.execute(statement, parameters)
  File "/home/ubuntu/.local/lib/python2.7/site-packages/MySQLdb/cursors.py", line 205, in execute
    self.errorhandler(self, exc, value)
  File "/home/ubuntu/.local/lib/python2.7/site-packages/MySQLdb/connections.py", line 36, in defaulterrorhandler
    raise errorclass, errorvalue
OperationalError: (_mysql_exceptions.OperationalError) (2006, 'MySQL server has gone away') [SQL: u'SELECT polls_prospect.id, polls_prospect.firstname, polls_prospect.lastname, polls_prospect.email \nFROM polls_prospect']
/home/ubuntu/.local/lib/python2.7/site-packages/sqlalchemy/dialects/mysql/base.py:2497: Warning: '@@tx_isolation' is deprecated and will be removed in a future release. Please use '@@transaction_isolation' instead
  cursor.execute('SELECT @@tx_isolation')
 * Serving Flask app "api_server" (lazy loading)
 * Environment: production
   WARNING: Do not use the development server in a production environment.
   Use a production WSGI server instead.
 * Debug mode: on
Traceback (most recent call last):
  File "api_server.py", line 117, in <module>
    app.run(host='0.0.0.0', port=5000)
  File "/home/ubuntu/.local/lib/python2.7/site-packages/flask/app.py", line 941, in run
    run_simple(host, port, self, **options)
  File "/home/ubuntu/.local/lib/python2.7/site-packages/werkzeug/serving.py", line 780, in run_simple
    s.bind((hostname, port))
  File "/usr/lib/python2.7/socket.py", line 228, in meth
    return getattr(self._sock,name)(*args)
socket.error: [Errno 98] Address already in use
Traceback (most recent call last):
  File "/home/ubuntu/.local/lib/python2.7/site-packages/flask/app.py", line 2301, in __call__
    return self.wsgi_app(environ, start_response)
  File "/home/ubuntu/.local/lib/python2.7/site-packages/flask/app.py", line 2287, in wsgi_app
    response = self.handle_exception(e)
  File "/home/ubuntu/.local/lib/python2.7/site-packages/flask/app.py", line 1733, in handle_exception
    reraise(exc_type, exc_value, tb)
  File "/home/ubuntu/.local/lib/python2.7/site-packages/flask/app.py", line 2284, in wsgi_app
    response = self.full_dispatch_request()
  File "/home/ubuntu/.local/lib/python2.7/site-packages/flask/app.py", line 1807, in full_dispatch_request
    rv = self.handle_user_exception(e)
  File "/home/ubuntu/.local/lib/python2.7/site-packages/flask/app.py", line 1710, in handle_user_exception
    reraise(exc_type, exc_value, tb)
  File "/home/ubuntu/.local/lib/python2.7/site-packages/flask/app.py", line 1805, in full_dispatch_request
    rv = self.dispatch_request()
  File "/home/ubuntu/.local/lib/python2.7/site-packages/flask/app.py", line 1791, in dispatch_request
    return self.view_functions[rule.endpoint](**req.view_args)
  File "/home/ubuntu/api_server/api_server.py", line 106, in get_tasks
    PPTable = getPollsProspect()
  File "/home/ubuntu/.local/lib/python2.7/site-packages/statsd/client.py", line 37, in _wrapped
    return_value = f(*args, **kwargs)
  File "/home/ubuntu/api_server/api_server.py", line 83, in getPollsProspect
    results = q.execute()
  File "/home/ubuntu/.local/lib/python2.7/site-packages/sqlalchemy/sql/base.py", line 386, in execute
    return e._execute_clauseelement(self, multiparams, params)
  File "/home/ubuntu/.local/lib/python2.7/site-packages/sqlalchemy/engine/base.py", line 1998, in _execute_clauseelement
    return connection._execute_clauseelement(elem, multiparams, params)
  File "/home/ubuntu/.local/lib/python2.7/site-packages/sqlalchemy/engine/base.py", line 1010, in _execute_clauseelement
    compiled_sql, distilled_params
  File "/home/ubuntu/.local/lib/python2.7/site-packages/sqlalchemy/engine/base.py", line 1146, in _execute_context
    context)
  File "/home/ubuntu/.local/lib/python2.7/site-packages/sqlalchemy/engine/base.py", line 1341, in _handle_dbapi_exception
    exc_info
  File "/home/ubuntu/.local/lib/python2.7/site-packages/sqlalchemy/util/compat.py", line 200, in raise_from_cause
    reraise(type(exception), exception, tb=exc_tb)
  File "/home/ubuntu/.local/lib/python2.7/site-packages/sqlalchemy/engine/base.py", line 1139, in _execute_context
    context)
  File "/home/ubuntu/.local/lib/python2.7/site-packages/sqlalchemy/engine/default.py", line 450, in do_execute
    cursor.execute(statement, parameters)
  File "/home/ubuntu/.local/lib/python2.7/site-packages/MySQLdb/cursors.py", line 205, in execute
    self.errorhandler(self, exc, value)
  File "/home/ubuntu/.local/lib/python2.7/site-packages/MySQLdb/connections.py", line 36, in defaulterrorhandler
    raise errorclass, errorvalue
OperationalError: (_mysql_exceptions.OperationalError) (2006, 'MySQL server has gone away') [SQL: u'SELECT polls_prospect.id, polls_prospect.firstname, polls_prospect.lastname, polls_prospect.email \nFROM polls_prospect']
Traceback (most recent call last):
  File "/home/ubuntu/.local/lib/python2.7/site-packages/flask/app.py", line 2301, in __call__
    return self.wsgi_app(environ, start_response)
  File "/home/ubuntu/.local/lib/python2.7/site-packages/flask/app.py", line 2287, in wsgi_app
    response = self.handle_exception(e)
  File "/home/ubuntu/.local/lib/python2.7/site-packages/flask/app.py", line 1733, in handle_exception
    reraise(exc_type, exc_value, tb)
  File "/home/ubuntu/.local/lib/python2.7/site-packages/flask/app.py", line 2284, in wsgi_app
    response = self.full_dispatch_request()
  File "/home/ubuntu/.local/lib/python2.7/site-packages/flask/app.py", line 1807, in full_dispatch_request
    rv = self.handle_user_exception(e)
  File "/home/ubuntu/.local/lib/python2.7/site-packages/flask/app.py", line 1710, in handle_user_exception
    reraise(exc_type, exc_value, tb)
  File "/home/ubuntu/.local/lib/python2.7/site-packages/flask/app.py", line 1805, in full_dispatch_request
    rv = self.dispatch_request()
  File "/home/ubuntu/.local/lib/python2.7/site-packages/flask/app.py", line 1791, in dispatch_request
    return self.view_functions[rule.endpoint](**req.view_args)
  File "/home/ubuntu/api_server/api_server.py", line 106, in get_tasks
    PPTable = getPollsProspect()
  File "/home/ubuntu/.local/lib/python2.7/site-packages/statsd/client.py", line 37, in _wrapped
    return_value = f(*args, **kwargs)
  File "/home/ubuntu/api_server/api_server.py", line 83, in getPollsProspect
    results = q.execute()
  File "/home/ubuntu/.local/lib/python2.7/site-packages/sqlalchemy/sql/base.py", line 386, in execute
    return e._execute_clauseelement(self, multiparams, params)
  File "/home/ubuntu/.local/lib/python2.7/site-packages/sqlalchemy/engine/base.py", line 1998, in _execute_clauseelement
    return connection._execute_clauseelement(elem, multiparams, params)
  File "/home/ubuntu/.local/lib/python2.7/site-packages/sqlalchemy/engine/base.py", line 1010, in _execute_clauseelement
    compiled_sql, distilled_params
  File "/home/ubuntu/.local/lib/python2.7/site-packages/sqlalchemy/engine/base.py", line 1146, in _execute_context
    context)
  File "/home/ubuntu/.local/lib/python2.7/site-packages/sqlalchemy/engine/base.py", line 1341, in _handle_dbapi_exception
    exc_info
  File "/home/ubuntu/.local/lib/python2.7/site-packages/sqlalchemy/util/compat.py", line 200, in raise_from_cause
    reraise(type(exception), exception, tb=exc_tb)
  File "/home/ubuntu/.local/lib/python2.7/site-packages/sqlalchemy/engine/base.py", line 1139, in _execute_context
    context)
  File "/home/ubuntu/.local/lib/python2.7/site-packages/sqlalchemy/engine/default.py", line 450, in do_execute
    cursor.execute(statement, parameters)
  File "/home/ubuntu/.local/lib/python2.7/site-packages/MySQLdb/cursors.py", line 205, in execute
    self.errorhandler(self, exc, value)
  File "/home/ubuntu/.local/lib/python2.7/site-packages/MySQLdb/connections.py", line 36, in defaulterrorhandler
    raise errorclass, errorvalue
OperationalError: (_mysql_exceptions.OperationalError) (2006, 'MySQL server has gone away') [SQL: u'SELECT polls_prospect.id, polls_prospect.firstname, polls_prospect.lastname, polls_prospect.email \nFROM polls_prospect']
Traceback (most recent call last):
  File "/home/ubuntu/.local/lib/python2.7/site-packages/flask/app.py", line 2301, in __call__
    return self.wsgi_app(environ, start_response)
  File "/home/ubuntu/.local/lib/python2.7/site-packages/flask/app.py", line 2287, in wsgi_app
    response = self.handle_exception(e)
  File "/home/ubuntu/.local/lib/python2.7/site-packages/flask/app.py", line 1733, in handle_exception
    reraise(exc_type, exc_value, tb)
  File "/home/ubuntu/.local/lib/python2.7/site-packages/flask/app.py", line 2284, in wsgi_app
    response = self.full_dispatch_request()
  File "/home/ubuntu/.local/lib/python2.7/site-packages/flask/app.py", line 1807, in full_dispatch_request
    rv = self.handle_user_exception(e)
  File "/home/ubuntu/.local/lib/python2.7/site-packages/flask/app.py", line 1710, in handle_user_exception
    reraise(exc_type, exc_value, tb)
  File "/home/ubuntu/.local/lib/python2.7/site-packages/flask/app.py", line 1805, in full_dispatch_request
    rv = self.dispatch_request()
  File "/home/ubuntu/.local/lib/python2.7/site-packages/flask/app.py", line 1791, in dispatch_request
    return self.view_functions[rule.endpoint](**req.view_args)
  File "/home/ubuntu/api_server/api_server.py", line 106, in get_tasks
    PPTable = getPollsProspect()
  File "/home/ubuntu/.local/lib/python2.7/site-packages/statsd/client.py", line 37, in _wrapped
    return_value = f(*args, **kwargs)
  File "/home/ubuntu/api_server/api_server.py", line 83, in getPollsProspect
    results = q.execute()
  File "/home/ubuntu/.local/lib/python2.7/site-packages/sqlalchemy/sql/base.py", line 386, in execute
    return e._execute_clauseelement(self, multiparams, params)
  File "/home/ubuntu/.local/lib/python2.7/site-packages/sqlalchemy/engine/base.py", line 1998, in _execute_clauseelement
    return connection._execute_clauseelement(elem, multiparams, params)
  File "/home/ubuntu/.local/lib/python2.7/site-packages/sqlalchemy/engine/base.py", line 1010, in _execute_clauseelement
    compiled_sql, distilled_params
  File "/home/ubuntu/.local/lib/python2.7/site-packages/sqlalchemy/engine/base.py", line 1146, in _execute_context
    context)
  File "/home/ubuntu/.local/lib/python2.7/site-packages/sqlalchemy/engine/base.py", line 1341, in _handle_dbapi_exception
    exc_info
  File "/home/ubuntu/.local/lib/python2.7/site-packages/sqlalchemy/util/compat.py", line 200, in raise_from_cause
    reraise(type(exception), exception, tb=exc_tb)
  File "/home/ubuntu/.local/lib/python2.7/site-packages/sqlalchemy/engine/base.py", line 1139, in _execute_context
    context)
  File "/home/ubuntu/.local/lib/python2.7/site-packages/sqlalchemy/engine/default.py", line 450, in do_execute
    cursor.execute(statement, parameters)
  File "/home/ubuntu/.local/lib/python2.7/site-packages/MySQLdb/cursors.py", line 205, in execute
    self.errorhandler(self, exc, value)
  File "/home/ubuntu/.local/lib/python2.7/site-packages/MySQLdb/connections.py", line 36, in defaulterrorhandler
    raise errorclass, errorvalue
OperationalError: (_mysql_exceptions.OperationalError) (2013, 'Lost connection to MySQL server during query') [SQL: u'SELECT polls_prospect.id, polls_prospect.firstname, polls_prospect.lastname, polls_prospect.email \nFROM polls_prospect']
Traceback (most recent call last):
  File "/home/ubuntu/.local/lib/python2.7/site-packages/flask/app.py", line 2301, in __call__
    return self.wsgi_app(environ, start_response)
  File "/home/ubuntu/.local/lib/python2.7/site-packages/flask/app.py", line 2287, in wsgi_app
    response = self.handle_exception(e)
  File "/home/ubuntu/.local/lib/python2.7/site-packages/flask/app.py", line 1733, in handle_exception
    reraise(exc_type, exc_value, tb)
  File "/home/ubuntu/.local/lib/python2.7/site-packages/flask/app.py", line 2284, in wsgi_app
    response = self.full_dispatch_request()
  File "/home/ubuntu/.local/lib/python2.7/site-packages/flask/app.py", line 1807, in full_dispatch_request
    rv = self.handle_user_exception(e)
  File "/home/ubuntu/.local/lib/python2.7/site-packages/flask/app.py", line 1710, in handle_user_exception
    reraise(exc_type, exc_value, tb)
  File "/home/ubuntu/.local/lib/python2.7/site-packages/flask/app.py", line 1805, in full_dispatch_request
    rv = self.dispatch_request()
  File "/home/ubuntu/.local/lib/python2.7/site-packages/flask/app.py", line 1791, in dispatch_request
    return self.view_functions[rule.endpoint](**req.view_args)
  File "/home/ubuntu/api_server/api_server.py", line 106, in get_tasks
    PPTable = getPollsProspect()
  File "/home/ubuntu/.local/lib/python2.7/site-packages/statsd/client.py", line 37, in _wrapped
    return_value = f(*args, **kwargs)
  File "/home/ubuntu/api_server/api_server.py", line 83, in getPollsProspect
    results = q.execute()
  File "/home/ubuntu/.local/lib/python2.7/site-packages/sqlalchemy/sql/base.py", line 386, in execute
    return e._execute_clauseelement(self, multiparams, params)
  File "/home/ubuntu/.local/lib/python2.7/site-packages/sqlalchemy/engine/base.py", line 1998, in _execute_clauseelement
    return connection._execute_clauseelement(elem, multiparams, params)
  File "/home/ubuntu/.local/lib/python2.7/site-packages/sqlalchemy/engine/base.py", line 1010, in _execute_clauseelement
    compiled_sql, distilled_params
  File "/home/ubuntu/.local/lib/python2.7/site-packages/sqlalchemy/engine/base.py", line 1146, in _execute_context
    context)
  File "/home/ubuntu/.local/lib/python2.7/site-packages/sqlalchemy/engine/base.py", line 1341, in _handle_dbapi_exception
    exc_info
  File "/home/ubuntu/.local/lib/python2.7/site-packages/sqlalchemy/util/compat.py", line 200, in raise_from_cause
    reraise(type(exception), exception, tb=exc_tb)
  File "/home/ubuntu/.local/lib/python2.7/site-packages/sqlalchemy/engine/base.py", line 1139, in _execute_context
    context)
  File "/home/ubuntu/.local/lib/python2.7/site-packages/sqlalchemy/engine/default.py", line 450, in do_execute
    cursor.execute(statement, parameters)
  File "/home/ubuntu/.local/lib/python2.7/site-packages/MySQLdb/cursors.py", line 205, in execute
    self.errorhandler(self, exc, value)
  File "/home/ubuntu/.local/lib/python2.7/site-packages/MySQLdb/connections.py", line 36, in defaulterrorhandler
    raise errorclass, errorvalue
OperationalError: (_mysql_exceptions.OperationalError) (2013, 'Lost connection to MySQL server during query') [SQL: u'SELECT polls_prospect.id, polls_prospect.firstname, polls_prospect.lastname, polls_prospect.email \nFROM polls_prospect']
Traceback (most recent call last):
  File "/home/ubuntu/.local/lib/python2.7/site-packages/flask/app.py", line 2301, in __call__
    return self.wsgi_app(environ, start_response)
  File "/home/ubuntu/.local/lib/python2.7/site-packages/flask/app.py", line 2287, in wsgi_app
    response = self.handle_exception(e)
  File "/home/ubuntu/.local/lib/python2.7/site-packages/flask/app.py", line 1733, in handle_exception
    reraise(exc_type, exc_value, tb)
  File "/home/ubuntu/.local/lib/python2.7/site-packages/flask/app.py", line 2284, in wsgi_app
    response = self.full_dispatch_request()
  File "/home/ubuntu/.local/lib/python2.7/site-packages/flask/app.py", line 1807, in full_dispatch_request
    rv = self.handle_user_exception(e)
  File "/home/ubuntu/.local/lib/python2.7/site-packages/flask/app.py", line 1710, in handle_user_exception
    reraise(exc_type, exc_value, tb)
  File "/home/ubuntu/.local/lib/python2.7/site-packages/flask/app.py", line 1805, in full_dispatch_request
    rv = self.dispatch_request()
  File "/home/ubuntu/.local/lib/python2.7/site-packages/flask/app.py", line 1791, in dispatch_request
    return self.view_functions[rule.endpoint](**req.view_args)
  File "/home/ubuntu/api_server/api_server.py", line 106, in get_tasks
    PPTable = getPollsProspect()
  File "/home/ubuntu/.local/lib/python2.7/site-packages/statsd/client.py", line 37, in _wrapped
    return_value = f(*args, **kwargs)
  File "/home/ubuntu/api_server/api_server.py", line 83, in getPollsProspect
    results = q.execute()
  File "/home/ubuntu/.local/lib/python2.7/site-packages/sqlalchemy/sql/base.py", line 386, in execute
    return e._execute_clauseelement(self, multiparams, params)
  File "/home/ubuntu/.local/lib/python2.7/site-packages/sqlalchemy/engine/base.py", line 1998, in _execute_clauseelement
    return connection._execute_clauseelement(elem, multiparams, params)
  File "/home/ubuntu/.local/lib/python2.7/site-packages/sqlalchemy/engine/base.py", line 1010, in _execute_clauseelement
    compiled_sql, distilled_params
  File "/home/ubuntu/.local/lib/python2.7/site-packages/sqlalchemy/engine/base.py", line 1146, in _execute_context
    context)
  File "/home/ubuntu/.local/lib/python2.7/site-packages/sqlalchemy/engine/base.py", line 1334, in _handle_dbapi_exception
    self._autorollback()
  File "/home/ubuntu/.local/lib/python2.7/site-packages/sqlalchemy/engine/base.py", line 791, in _autorollback
    self._root._rollback_impl()
  File "/home/ubuntu/.local/lib/python2.7/site-packages/sqlalchemy/engine/base.py", line 670, in _rollback_impl
    self._handle_dbapi_exception(e, None, None, None, None)
  File "/home/ubuntu/.local/lib/python2.7/site-packages/sqlalchemy/engine/base.py", line 1266, in _handle_dbapi_exception
    exc_info
  File "/home/ubuntu/.local/lib/python2.7/site-packages/sqlalchemy/util/compat.py", line 200, in raise_from_cause
    reraise(type(exception), exception, tb=exc_tb)
  File "/home/ubuntu/.local/lib/python2.7/site-packages/sqlalchemy/engine/base.py", line 668, in _rollback_impl
    self.engine.dialect.do_rollback(self.connection)
  File "/home/ubuntu/.local/lib/python2.7/site-packages/sqlalchemy/dialects/mysql/base.py", line 2526, in do_rollback
    dbapi_connection.rollback()
OperationalError: (_mysql_exceptions.OperationalError) (2013, 'Lost connection to MySQL server during query')
Traceback (most recent call last):
  File "/home/ubuntu/.local/lib/python2.7/site-packages/flask/app.py", line 2301, in __call__
    return self.wsgi_app(environ, start_response)
  File "/home/ubuntu/.local/lib/python2.7/site-packages/flask/app.py", line 2287, in wsgi_app
    response = self.handle_exception(e)
  File "/home/ubuntu/.local/lib/python2.7/site-packages/flask/app.py", line 1733, in handle_exception
    reraise(exc_type, exc_value, tb)
  File "/home/ubuntu/.local/lib/python2.7/site-packages/flask/app.py", line 2284, in wsgi_app
    response = self.full_dispatch_request()
  File "/home/ubuntu/.local/lib/python2.7/site-packages/flask/app.py", line 1807, in full_dispatch_request
    rv = self.handle_user_exception(e)
  File "/home/ubuntu/.local/lib/python2.7/site-packages/flask/app.py", line 1710, in handle_user_exception
    reraise(exc_type, exc_value, tb)
  File "/home/ubuntu/.local/lib/python2.7/site-packages/flask/app.py", line 1805, in full_dispatch_request
    rv = self.dispatch_request()
  File "/home/ubuntu/.local/lib/python2.7/site-packages/flask/app.py", line 1791, in dispatch_request
    return self.view_functions[rule.endpoint](**req.view_args)
  File "/home/ubuntu/api_server/api_server.py", line 106, in get_tasks
    PPTable = getPollsProspect()
  File "/home/ubuntu/.local/lib/python2.7/site-packages/statsd/client.py", line 37, in _wrapped
    return_value = f(*args, **kwargs)
  File "/home/ubuntu/api_server/api_server.py", line 83, in getPollsProspect
    results = q.execute()
  File "/home/ubuntu/.local/lib/python2.7/site-packages/sqlalchemy/sql/base.py", line 386, in execute
    return e._execute_clauseelement(self, multiparams, params)
  File "/home/ubuntu/.local/lib/python2.7/site-packages/sqlalchemy/engine/base.py", line 1998, in _execute_clauseelement
    return connection._execute_clauseelement(elem, multiparams, params)
  File "/home/ubuntu/.local/lib/python2.7/site-packages/sqlalchemy/engine/base.py", line 1010, in _execute_clauseelement
    compiled_sql, distilled_params
  File "/home/ubuntu/.local/lib/python2.7/site-packages/sqlalchemy/engine/base.py", line 1146, in _execute_context
    context)
  File "/home/ubuntu/.local/lib/python2.7/site-packages/sqlalchemy/engine/base.py", line 1341, in _handle_dbapi_exception
    exc_info
  File "/home/ubuntu/.local/lib/python2.7/site-packages/sqlalchemy/util/compat.py", line 200, in raise_from_cause
    reraise(type(exception), exception, tb=exc_tb)
  File "/home/ubuntu/.local/lib/python2.7/site-packages/sqlalchemy/engine/base.py", line 1139, in _execute_context
    context)
  File "/home/ubuntu/.local/lib/python2.7/site-packages/sqlalchemy/engine/default.py", line 450, in do_execute
    cursor.execute(statement, parameters)
  File "/home/ubuntu/.local/lib/python2.7/site-packages/MySQLdb/cursors.py", line 205, in execute
    self.errorhandler(self, exc, value)
  File "/home/ubuntu/.local/lib/python2.7/site-packages/MySQLdb/connections.py", line 36, in defaulterrorhandler
    raise errorclass, errorvalue
OperationalError: (_mysql_exceptions.OperationalError) (2013, 'Lost connection to MySQL server during query') [SQL: u'SELECT polls_prospect.id, polls_prospect.firstname, polls_prospect.lastname, polls_prospect.email \nFROM polls_prospect']
Traceback (most recent call last):
  File "/home/ubuntu/.local/lib/python2.7/site-packages/flask/app.py", line 2301, in __call__
    return self.wsgi_app(environ, start_response)
  File "/home/ubuntu/.local/lib/python2.7/site-packages/flask/app.py", line 2287, in wsgi_app
    response = self.handle_exception(e)
  File "/home/ubuntu/.local/lib/python2.7/site-packages/flask/app.py", line 1733, in handle_exception
    reraise(exc_type, exc_value, tb)
  File "/home/ubuntu/.local/lib/python2.7/site-packages/flask/app.py", line 2284, in wsgi_app
    response = self.full_dispatch_request()
  File "/home/ubuntu/.local/lib/python2.7/site-packages/flask/app.py", line 1807, in full_dispatch_request
    rv = self.handle_user_exception(e)
  File "/home/ubuntu/.local/lib/python2.7/site-packages/flask/app.py", line 1710, in handle_user_exception
    reraise(exc_type, exc_value, tb)
  File "/home/ubuntu/.local/lib/python2.7/site-packages/flask/app.py", line 1805, in full_dispatch_request
    rv = self.dispatch_request()
  File "/home/ubuntu/.local/lib/python2.7/site-packages/flask/app.py", line 1791, in dispatch_request
    return self.view_functions[rule.endpoint](**req.view_args)
  File "/home/ubuntu/api_server/api_server.py", line 106, in get_tasks
    PPTable = getPollsProspect()
  File "/home/ubuntu/.local/lib/python2.7/site-packages/statsd/client.py", line 37, in _wrapped
    return_value = f(*args, **kwargs)
  File "/home/ubuntu/api_server/api_server.py", line 83, in getPollsProspect
    results = q.execute()
  File "/home/ubuntu/.local/lib/python2.7/site-packages/sqlalchemy/sql/base.py", line 386, in execute
    return e._execute_clauseelement(self, multiparams, params)
  File "/home/ubuntu/.local/lib/python2.7/site-packages/sqlalchemy/engine/base.py", line 1998, in _execute_clauseelement
    return connection._execute_clauseelement(elem, multiparams, params)
  File "/home/ubuntu/.local/lib/python2.7/site-packages/sqlalchemy/engine/base.py", line 1010, in _execute_clauseelement
    compiled_sql, distilled_params
  File "/home/ubuntu/.local/lib/python2.7/site-packages/sqlalchemy/engine/base.py", line 1146, in _execute_context
    context)
  File "/home/ubuntu/.local/lib/python2.7/site-packages/sqlalchemy/engine/base.py", line 1334, in _handle_dbapi_exception
    self._autorollback()
  File "/home/ubuntu/.local/lib/python2.7/site-packages/sqlalchemy/engine/base.py", line 791, in _autorollback
    self._root._rollback_impl()
  File "/home/ubuntu/.local/lib/python2.7/site-packages/sqlalchemy/engine/base.py", line 670, in _rollback_impl
    self._handle_dbapi_exception(e, None, None, None, None)
  File "/home/ubuntu/.local/lib/python2.7/site-packages/sqlalchemy/engine/base.py", line 1266, in _handle_dbapi_exception
    exc_info
  File "/home/ubuntu/.local/lib/python2.7/site-packages/sqlalchemy/util/compat.py", line 200, in raise_from_cause
    reraise(type(exception), exception, tb=exc_tb)
  File "/home/ubuntu/.local/lib/python2.7/site-packages/sqlalchemy/engine/base.py", line 668, in _rollback_impl
    self.engine.dialect.do_rollback(self.connection)
  File "/home/ubuntu/.local/lib/python2.7/site-packages/sqlalchemy/dialects/mysql/base.py", line 2526, in do_rollback
    dbapi_connection.rollback()
OperationalError: (_mysql_exceptions.OperationalError) (2013, 'Lost connection to MySQL server during query')
Traceback (most recent call last):
  File "/home/ubuntu/.local/lib/python2.7/site-packages/flask/app.py", line 2301, in __call__
    return self.wsgi_app(environ, start_response)
  File "/home/ubuntu/.local/lib/python2.7/site-packages/flask/app.py", line 2287, in wsgi_app
    response = self.handle_exception(e)
  File "/home/ubuntu/.local/lib/python2.7/site-packages/flask/app.py", line 1733, in handle_exception
    reraise(exc_type, exc_value, tb)
  File "/home/ubuntu/.local/lib/python2.7/site-packages/flask/app.py", line 2284, in wsgi_app
    response = self.full_dispatch_request()
  File "/home/ubuntu/.local/lib/python2.7/site-packages/flask/app.py", line 1807, in full_dispatch_request
    rv = self.handle_user_exception(e)
  File "/home/ubuntu/.local/lib/python2.7/site-packages/flask/app.py", line 1710, in handle_user_exception
    reraise(exc_type, exc_value, tb)
  File "/home/ubuntu/.local/lib/python2.7/site-packages/flask/app.py", line 1805, in full_dispatch_request
    rv = self.dispatch_request()
  File "/home/ubuntu/.local/lib/python2.7/site-packages/flask/app.py", line 1791, in dispatch_request
    return self.view_functions[rule.endpoint](**req.view_args)
  File "/home/ubuntu/api_server/api_server.py", line 106, in get_tasks
    PPTable = getPollsProspect()
  File "/home/ubuntu/.local/lib/python2.7/site-packages/statsd/client.py", line 37, in _wrapped
    return_value = f(*args, **kwargs)
  File "/home/ubuntu/api_server/api_server.py", line 83, in getPollsProspect
    results = q.execute()
  File "/home/ubuntu/.local/lib/python2.7/site-packages/sqlalchemy/sql/base.py", line 386, in execute
    return e._execute_clauseelement(self, multiparams, params)
  File "/home/ubuntu/.local/lib/python2.7/site-packages/sqlalchemy/engine/base.py", line 1998, in _execute_clauseelement
    return connection._execute_clauseelement(elem, multiparams, params)
  File "/home/ubuntu/.local/lib/python2.7/site-packages/sqlalchemy/engine/base.py", line 1010, in _execute_clauseelement
    compiled_sql, distilled_params
  File "/home/ubuntu/.local/lib/python2.7/site-packages/sqlalchemy/engine/base.py", line 1146, in _execute_context
    context)
  File "/home/ubuntu/.local/lib/python2.7/site-packages/sqlalchemy/engine/base.py", line 1341, in _handle_dbapi_exception
    exc_info
  File "/home/ubuntu/.local/lib/python2.7/site-packages/sqlalchemy/util/compat.py", line 200, in raise_from_cause
    reraise(type(exception), exception, tb=exc_tb)
  File "/home/ubuntu/.local/lib/python2.7/site-packages/sqlalchemy/engine/base.py", line 1139, in _execute_context
    context)
  File "/home/ubuntu/.local/lib/python2.7/site-packages/sqlalchemy/engine/default.py", line 450, in do_execute
    cursor.execute(statement, parameters)
  File "/home/ubuntu/.local/lib/python2.7/site-packages/MySQLdb/cursors.py", line 205, in execute
    self.errorhandler(self, exc, value)
  File "/home/ubuntu/.local/lib/python2.7/site-packages/MySQLdb/connections.py", line 36, in defaulterrorhandler
    raise errorclass, errorvalue
OperationalError: (_mysql_exceptions.OperationalError) (2013, 'Lost connection to MySQL server during query') [SQL: u'SELECT polls_prospect.id, polls_prospect.firstname, polls_prospect.lastname, polls_prospect.email \nFROM polls_prospect']
Traceback (most recent call last):
  File "/home/ubuntu/.local/lib/python2.7/site-packages/flask/app.py", line 2301, in __call__
    return self.wsgi_app(environ, start_response)
  File "/home/ubuntu/.local/lib/python2.7/site-packages/flask/app.py", line 2287, in wsgi_app
    response = self.handle_exception(e)
  File "/home/ubuntu/.local/lib/python2.7/site-packages/flask/app.py", line 1733, in handle_exception
    reraise(exc_type, exc_value, tb)
  File "/home/ubuntu/.local/lib/python2.7/site-packages/flask/app.py", line 2284, in wsgi_app
    response = self.full_dispatch_request()
  File "/home/ubuntu/.local/lib/python2.7/site-packages/flask/app.py", line 1807, in full_dispatch_request
    rv = self.handle_user_exception(e)
  File "/home/ubuntu/.local/lib/python2.7/site-packages/flask/app.py", line 1710, in handle_user_exception
    reraise(exc_type, exc_value, tb)
  File "/home/ubuntu/.local/lib/python2.7/site-packages/flask/app.py", line 1805, in full_dispatch_request
    rv = self.dispatch_request()
  File "/home/ubuntu/.local/lib/python2.7/site-packages/flask/app.py", line 1791, in dispatch_request
    return self.view_functions[rule.endpoint](**req.view_args)
  File "/home/ubuntu/api_server/api_server.py", line 106, in get_tasks
    PPTable = getPollsProspect()
  File "/home/ubuntu/.local/lib/python2.7/site-packages/statsd/client.py", line 37, in _wrapped
    return_value = f(*args, **kwargs)
  File "/home/ubuntu/api_server/api_server.py", line 83, in getPollsProspect
    results = q.execute()
  File "/home/ubuntu/.local/lib/python2.7/site-packages/sqlalchemy/sql/base.py", line 386, in execute
    return e._execute_clauseelement(self, multiparams, params)
  File "/home/ubuntu/.local/lib/python2.7/site-packages/sqlalchemy/engine/base.py", line 1998, in _execute_clauseelement
    return connection._execute_clauseelement(elem, multiparams, params)
  File "/home/ubuntu/.local/lib/python2.7/site-packages/sqlalchemy/engine/base.py", line 1010, in _execute_clauseelement
    compiled_sql, distilled_params
  File "/home/ubuntu/.local/lib/python2.7/site-packages/sqlalchemy/engine/base.py", line 1146, in _execute_context
    context)
  File "/home/ubuntu/.local/lib/python2.7/site-packages/sqlalchemy/engine/base.py", line 1341, in _handle_dbapi_exception
    exc_info
  File "/home/ubuntu/.local/lib/python2.7/site-packages/sqlalchemy/util/compat.py", line 200, in raise_from_cause
    reraise(type(exception), exception, tb=exc_tb)
  File "/home/ubuntu/.local/lib/python2.7/site-packages/sqlalchemy/engine/base.py", line 1139, in _execute_context
    context)
  File "/home/ubuntu/.local/lib/python2.7/site-packages/sqlalchemy/engine/default.py", line 450, in do_execute
    cursor.execute(statement, parameters)
  File "/home/ubuntu/.local/lib/python2.7/site-packages/MySQLdb/cursors.py", line 205, in execute
    self.errorhandler(self, exc, value)
  File "/home/ubuntu/.local/lib/python2.7/site-packages/MySQLdb/connections.py", line 36, in defaulterrorhandler
    raise errorclass, errorvalue
OperationalError: (_mysql_exceptions.OperationalError) (2013, 'Lost connection to MySQL server during query') [SQL: u'SELECT polls_prospect.id, polls_prospect.firstname, polls_prospect.lastname, polls_prospect.email \nFROM polls_prospect']
Traceback (most recent call last):
  File "/home/ubuntu/.local/lib/python2.7/site-packages/flask/app.py", line 2301, in __call__
    return self.wsgi_app(environ, start_response)
  File "/home/ubuntu/.local/lib/python2.7/site-packages/flask/app.py", line 2287, in wsgi_app
    response = self.handle_exception(e)
  File "/home/ubuntu/.local/lib/python2.7/site-packages/flask/app.py", line 1733, in handle_exception
    reraise(exc_type, exc_value, tb)
  File "/home/ubuntu/.local/lib/python2.7/site-packages/flask/app.py", line 2284, in wsgi_app
    response = self.full_dispatch_request()
  File "/home/ubuntu/.local/lib/python2.7/site-packages/flask/app.py", line 1807, in full_dispatch_request
    rv = self.handle_user_exception(e)
  File "/home/ubuntu/.local/lib/python2.7/site-packages/flask/app.py", line 1710, in handle_user_exception
    reraise(exc_type, exc_value, tb)
  File "/home/ubuntu/.local/lib/python2.7/site-packages/flask/app.py", line 1805, in full_dispatch_request
    rv = self.dispatch_request()
  File "/home/ubuntu/.local/lib/python2.7/site-packages/flask/app.py", line 1791, in dispatch_request
    return self.view_functions[rule.endpoint](**req.view_args)
  File "/home/ubuntu/api_server/api_server.py", line 106, in get_tasks
    PPTable = getPollsProspect()
  File "/home/ubuntu/.local/lib/python2.7/site-packages/statsd/client.py", line 37, in _wrapped
    return_value = f(*args, **kwargs)
  File "/home/ubuntu/api_server/api_server.py", line 83, in getPollsProspect
    results = q.execute()
  File "/home/ubuntu/.local/lib/python2.7/site-packages/sqlalchemy/sql/base.py", line 386, in execute
    return e._execute_clauseelement(self, multiparams, params)
  File "/home/ubuntu/.local/lib/python2.7/site-packages/sqlalchemy/engine/base.py", line 1998, in _execute_clauseelement
    return connection._execute_clauseelement(elem, multiparams, params)
  File "/home/ubuntu/.local/lib/python2.7/site-packages/sqlalchemy/engine/base.py", line 1010, in _execute_clauseelement
    compiled_sql, distilled_params
  File "/home/ubuntu/.local/lib/python2.7/site-packages/sqlalchemy/engine/base.py", line 1146, in _execute_context
    context)
  File "/home/ubuntu/.local/lib/python2.7/site-packages/sqlalchemy/engine/base.py", line 1341, in _handle_dbapi_exception
    exc_info
  File "/home/ubuntu/.local/lib/python2.7/site-packages/sqlalchemy/util/compat.py", line 200, in raise_from_cause
    reraise(type(exception), exception, tb=exc_tb)
  File "/home/ubuntu/.local/lib/python2.7/site-packages/sqlalchemy/engine/base.py", line 1139, in _execute_context
    context)
  File "/home/ubuntu/.local/lib/python2.7/site-packages/sqlalchemy/engine/default.py", line 450, in do_execute
    cursor.execute(statement, parameters)
  File "/home/ubuntu/.local/lib/python2.7/site-packages/MySQLdb/cursors.py", line 205, in execute
    self.errorhandler(self, exc, value)
  File "/home/ubuntu/.local/lib/python2.7/site-packages/MySQLdb/connections.py", line 36, in defaulterrorhandler
    raise errorclass, errorvalue
OperationalError: (_mysql_exceptions.OperationalError) (2013, 'Lost connection to MySQL server during query') [SQL: u'SELECT polls_prospect.id, polls_prospect.firstname, polls_prospect.lastname, polls_prospect.email \nFROM polls_prospect']
Traceback (most recent call last):
  File "/home/ubuntu/.local/lib/python2.7/site-packages/flask/app.py", line 2301, in __call__
    return self.wsgi_app(environ, start_response)
  File "/home/ubuntu/.local/lib/python2.7/site-packages/flask/app.py", line 2287, in wsgi_app
    response = self.handle_exception(e)
  File "/home/ubuntu/.local/lib/python2.7/site-packages/flask/app.py", line 1733, in handle_exception
    reraise(exc_type, exc_value, tb)
  File "/home/ubuntu/.local/lib/python2.7/site-packages/flask/app.py", line 2284, in wsgi_app
    response = self.full_dispatch_request()
  File "/home/ubuntu/.local/lib/python2.7/site-packages/flask/app.py", line 1807, in full_dispatch_request
    rv = self.handle_user_exception(e)
  File "/home/ubuntu/.local/lib/python2.7/site-packages/flask/app.py", line 1710, in handle_user_exception
    reraise(exc_type, exc_value, tb)
  File "/home/ubuntu/.local/lib/python2.7/site-packages/flask/app.py", line 1805, in full_dispatch_request
    rv = self.dispatch_request()
  File "/home/ubuntu/.local/lib/python2.7/site-packages/flask/app.py", line 1791, in dispatch_request
    return self.view_functions[rule.endpoint](**req.view_args)
  File "/home/ubuntu/api_server/api_server.py", line 106, in get_tasks
    PPTable = getPollsProspect()
  File "/home/ubuntu/.local/lib/python2.7/site-packages/statsd/client.py", line 37, in _wrapped
    return_value = f(*args, **kwargs)
  File "/home/ubuntu/api_server/api_server.py", line 83, in getPollsProspect
    results = q.execute()
  File "/home/ubuntu/.local/lib/python2.7/site-packages/sqlalchemy/sql/base.py", line 386, in execute
    return e._execute_clauseelement(self, multiparams, params)
  File "/home/ubuntu/.local/lib/python2.7/site-packages/sqlalchemy/engine/base.py", line 1998, in _execute_clauseelement
    return connection._execute_clauseelement(elem, multiparams, params)
  File "/home/ubuntu/.local/lib/python2.7/site-packages/sqlalchemy/engine/base.py", line 1010, in _execute_clauseelement
    compiled_sql, distilled_params
  File "/home/ubuntu/.local/lib/python2.7/site-packages/sqlalchemy/engine/base.py", line 1146, in _execute_context
    context)
  File "/home/ubuntu/.local/lib/python2.7/site-packages/sqlalchemy/engine/base.py", line 1341, in _handle_dbapi_exception
    exc_info
  File "/home/ubuntu/.local/lib/python2.7/site-packages/sqlalchemy/util/compat.py", line 200, in raise_from_cause
    reraise(type(exception), exception, tb=exc_tb)
  File "/home/ubuntu/.local/lib/python2.7/site-packages/sqlalchemy/engine/base.py", line 1139, in _execute_context
    context)
  File "/home/ubuntu/.local/lib/python2.7/site-packages/sqlalchemy/engine/default.py", line 450, in do_execute
    cursor.execute(statement, parameters)
  File "/home/ubuntu/.local/lib/python2.7/site-packages/MySQLdb/cursors.py", line 205, in execute
    self.errorhandler(self, exc, value)
  File "/home/ubuntu/.local/lib/python2.7/site-packages/MySQLdb/connections.py", line 36, in defaulterrorhandler
    raise errorclass, errorvalue
OperationalError: (_mysql_exceptions.OperationalError) (2013, 'Lost connection to MySQL server during query') [SQL: u'SELECT polls_prospect.id, polls_prospect.firstname, polls_prospect.lastname, polls_prospect.email \nFROM polls_prospect']
Traceback (most recent call last):
  File "/home/ubuntu/.local/lib/python2.7/site-packages/flask/app.py", line 2301, in __call__
    return self.wsgi_app(environ, start_response)
  File "/home/ubuntu/.local/lib/python2.7/site-packages/flask/app.py", line 2287, in wsgi_app
    response = self.handle_exception(e)
  File "/home/ubuntu/.local/lib/python2.7/site-packages/flask/app.py", line 1733, in handle_exception
    reraise(exc_type, exc_value, tb)
  File "/home/ubuntu/.local/lib/python2.7/site-packages/flask/app.py", line 2284, in wsgi_app
    response = self.full_dispatch_request()
  File "/home/ubuntu/.local/lib/python2.7/site-packages/flask/app.py", line 1807, in full_dispatch_request
    rv = self.handle_user_exception(e)
  File "/home/ubuntu/.local/lib/python2.7/site-packages/flask/app.py", line 1710, in handle_user_exception
    reraise(exc_type, exc_value, tb)
  File "/home/ubuntu/.local/lib/python2.7/site-packages/flask/app.py", line 1805, in full_dispatch_request
    rv = self.dispatch_request()
  File "/home/ubuntu/.local/lib/python2.7/site-packages/flask/app.py", line 1791, in dispatch_request
    return self.view_functions[rule.endpoint](**req.view_args)
  File "/home/ubuntu/api_server/api_server.py", line 106, in get_tasks
    PPTable = getPollsProspect()
  File "/home/ubuntu/.local/lib/python2.7/site-packages/statsd/client.py", line 37, in _wrapped
    return_value = f(*args, **kwargs)
  File "/home/ubuntu/api_server/api_server.py", line 83, in getPollsProspect
    results = q.execute()
  File "/home/ubuntu/.local/lib/python2.7/site-packages/sqlalchemy/sql/base.py", line 386, in execute
    return e._execute_clauseelement(self, multiparams, params)
  File "/home/ubuntu/.local/lib/python2.7/site-packages/sqlalchemy/engine/base.py", line 1998, in _execute_clauseelement
    return connection._execute_clauseelement(elem, multiparams, params)
  File "/home/ubuntu/.local/lib/python2.7/site-packages/sqlalchemy/engine/base.py", line 1010, in _execute_clauseelement
    compiled_sql, distilled_params
  File "/home/ubuntu/.local/lib/python2.7/site-packages/sqlalchemy/engine/base.py", line 1146, in _execute_context
    context)
  File "/home/ubuntu/.local/lib/python2.7/site-packages/sqlalchemy/engine/base.py", line 1341, in _handle_dbapi_exception
    exc_info
  File "/home/ubuntu/.local/lib/python2.7/site-packages/sqlalchemy/util/compat.py", line 200, in raise_from_cause
    reraise(type(exception), exception, tb=exc_tb)
  File "/home/ubuntu/.local/lib/python2.7/site-packages/sqlalchemy/engine/base.py", line 1139, in _execute_context
    context)
  File "/home/ubuntu/.local/lib/python2.7/site-packages/sqlalchemy/engine/default.py", line 450, in do_execute
    cursor.execute(statement, parameters)
  File "/home/ubuntu/.local/lib/python2.7/site-packages/MySQLdb/cursors.py", line 205, in execute
    self.errorhandler(self, exc, value)
  File "/home/ubuntu/.local/lib/python2.7/site-packages/MySQLdb/connections.py", line 36, in defaulterrorhandler
    raise errorclass, errorvalue
OperationalError: (_mysql_exceptions.OperationalError) (2013, 'Lost connection to MySQL server during query') [SQL: u'SELECT polls_prospect.id, polls_prospect.firstname, polls_prospect.lastname, polls_prospect.email \nFROM polls_prospect']
Traceback (most recent call last):
  File "/home/ubuntu/.local/lib/python2.7/site-packages/flask/app.py", line 2301, in __call__
    return self.wsgi_app(environ, start_response)
  File "/home/ubuntu/.local/lib/python2.7/site-packages/flask/app.py", line 2287, in wsgi_app
    response = self.handle_exception(e)
  File "/home/ubuntu/.local/lib/python2.7/site-packages/flask/app.py", line 1733, in handle_exception
    reraise(exc_type, exc_value, tb)
  File "/home/ubuntu/.local/lib/python2.7/site-packages/flask/app.py", line 2284, in wsgi_app
    response = self.full_dispatch_request()
  File "/home/ubuntu/.local/lib/python2.7/site-packages/flask/app.py", line 1807, in full_dispatch_request
    rv = self.handle_user_exception(e)
  File "/home/ubuntu/.local/lib/python2.7/site-packages/flask/app.py", line 1710, in handle_user_exception
    reraise(exc_type, exc_value, tb)
  File "/home/ubuntu/.local/lib/python2.7/site-packages/flask/app.py", line 1805, in full_dispatch_request
    rv = self.dispatch_request()
  File "/home/ubuntu/.local/lib/python2.7/site-packages/flask/app.py", line 1791, in dispatch_request
    return self.view_functions[rule.endpoint](**req.view_args)
  File "/home/ubuntu/api_server/api_server.py", line 106, in get_tasks
    PPTable = getPollsProspect()
  File "/home/ubuntu/.local/lib/python2.7/site-packages/statsd/client.py", line 37, in _wrapped
    return_value = f(*args, **kwargs)
  File "/home/ubuntu/api_server/api_server.py", line 83, in getPollsProspect
    results = q.execute()
  File "/home/ubuntu/.local/lib/python2.7/site-packages/sqlalchemy/sql/base.py", line 386, in execute
    return e._execute_clauseelement(self, multiparams, params)
  File "/home/ubuntu/.local/lib/python2.7/site-packages/sqlalchemy/engine/base.py", line 1998, in _execute_clauseelement
    return connection._execute_clauseelement(elem, multiparams, params)
  File "/home/ubuntu/.local/lib/python2.7/site-packages/sqlalchemy/engine/base.py", line 1010, in _execute_clauseelement
    compiled_sql, distilled_params
  File "/home/ubuntu/.local/lib/python2.7/site-packages/sqlalchemy/engine/base.py", line 1146, in _execute_context
    context)
  File "/home/ubuntu/.local/lib/python2.7/site-packages/sqlalchemy/engine/base.py", line 1341, in _handle_dbapi_exception
    exc_info
  File "/home/ubuntu/.local/lib/python2.7/site-packages/sqlalchemy/util/compat.py", line 200, in raise_from_cause
    reraise(type(exception), exception, tb=exc_tb)
  File "/home/ubuntu/.local/lib/python2.7/site-packages/sqlalchemy/engine/base.py", line 1139, in _execute_context
    context)
  File "/home/ubuntu/.local/lib/python2.7/site-packages/sqlalchemy/engine/default.py", line 450, in do_execute
    cursor.execute(statement, parameters)
  File "/home/ubuntu/.local/lib/python2.7/site-packages/MySQLdb/cursors.py", line 205, in execute
    self.errorhandler(self, exc, value)
  File "/home/ubuntu/.local/lib/python2.7/site-packages/MySQLdb/connections.py", line 36, in defaulterrorhandler
    raise errorclass, errorvalue
OperationalError: (_mysql_exceptions.OperationalError) (2013, 'Lost connection to MySQL server during query') [SQL: u'SELECT polls_prospect.id, polls_prospect.firstname, polls_prospect.lastname, polls_prospect.email \nFROM polls_prospect']
Traceback (most recent call last):
  File "/home/ubuntu/.local/lib/python2.7/site-packages/flask/app.py", line 2301, in __call__
    return self.wsgi_app(environ, start_response)
  File "/home/ubuntu/.local/lib/python2.7/site-packages/flask/app.py", line 2287, in wsgi_app
    response = self.handle_exception(e)
  File "/home/ubuntu/.local/lib/python2.7/site-packages/flask/app.py", line 1733, in handle_exception
    reraise(exc_type, exc_value, tb)
  File "/home/ubuntu/.local/lib/python2.7/site-packages/flask/app.py", line 2284, in wsgi_app
    response = self.full_dispatch_request()
  File "/home/ubuntu/.local/lib/python2.7/site-packages/flask/app.py", line 1807, in full_dispatch_request
    rv = self.handle_user_exception(e)
  File "/home/ubuntu/.local/lib/python2.7/site-packages/flask/app.py", line 1710, in handle_user_exception
    reraise(exc_type, exc_value, tb)
  File "/home/ubuntu/.local/lib/python2.7/site-packages/flask/app.py", line 1805, in full_dispatch_request
    rv = self.dispatch_request()
  File "/home/ubuntu/.local/lib/python2.7/site-packages/flask/app.py", line 1791, in dispatch_request
    return self.view_functions[rule.endpoint](**req.view_args)
  File "/home/ubuntu/api_server/api_server.py", line 106, in get_tasks
    PPTable = getPollsProspect()
  File "/home/ubuntu/.local/lib/python2.7/site-packages/statsd/client.py", line 37, in _wrapped
    return_value = f(*args, **kwargs)
  File "/home/ubuntu/api_server/api_server.py", line 83, in getPollsProspect
    results = q.execute()
  File "/home/ubuntu/.local/lib/python2.7/site-packages/sqlalchemy/sql/base.py", line 386, in execute
    return e._execute_clauseelement(self, multiparams, params)
  File "/home/ubuntu/.local/lib/python2.7/site-packages/sqlalchemy/engine/base.py", line 1998, in _execute_clauseelement
    return connection._execute_clauseelement(elem, multiparams, params)
  File "/home/ubuntu/.local/lib/python2.7/site-packages/sqlalchemy/engine/base.py", line 1010, in _execute_clauseelement
    compiled_sql, distilled_params
  File "/home/ubuntu/.local/lib/python2.7/site-packages/sqlalchemy/engine/base.py", line 1146, in _execute_context
    context)
  File "/home/ubuntu/.local/lib/python2.7/site-packages/sqlalchemy/engine/base.py", line 1341, in _handle_dbapi_exception
    exc_info
  File "/home/ubuntu/.local/lib/python2.7/site-packages/sqlalchemy/util/compat.py", line 200, in raise_from_cause
    reraise(type(exception), exception, tb=exc_tb)
  File "/home/ubuntu/.local/lib/python2.7/site-packages/sqlalchemy/engine/base.py", line 1139, in _execute_context
    context)
  File "/home/ubuntu/.local/lib/python2.7/site-packages/sqlalchemy/engine/default.py", line 450, in do_execute
    cursor.execute(statement, parameters)
  File "/home/ubuntu/.local/lib/python2.7/site-packages/MySQLdb/cursors.py", line 205, in execute
    self.errorhandler(self, exc, value)
  File "/home/ubuntu/.local/lib/python2.7/site-packages/MySQLdb/connections.py", line 36, in defaulterrorhandler
    raise errorclass, errorvalue
OperationalError: (_mysql_exceptions.OperationalError) (2013, 'Lost connection to MySQL server during query') [SQL: u'SELECT polls_prospect.id, polls_prospect.firstname, polls_prospect.lastname, polls_prospect.email \nFROM polls_prospect']
Traceback (most recent call last):
  File "/home/ubuntu/.local/lib/python2.7/site-packages/flask/app.py", line 2301, in __call__
    return self.wsgi_app(environ, start_response)
  File "/home/ubuntu/.local/lib/python2.7/site-packages/flask/app.py", line 2287, in wsgi_app
    response = self.handle_exception(e)
  File "/home/ubuntu/.local/lib/python2.7/site-packages/flask/app.py", line 1733, in handle_exception
    reraise(exc_type, exc_value, tb)
  File "/home/ubuntu/.local/lib/python2.7/site-packages/flask/app.py", line 2284, in wsgi_app
    response = self.full_dispatch_request()
  File "/home/ubuntu/.local/lib/python2.7/site-packages/flask/app.py", line 1807, in full_dispatch_request
    rv = self.handle_user_exception(e)
  File "/home/ubuntu/.local/lib/python2.7/site-packages/flask/app.py", line 1710, in handle_user_exception
    reraise(exc_type, exc_value, tb)
  File "/home/ubuntu/.local/lib/python2.7/site-packages/flask/app.py", line 1805, in full_dispatch_request
    rv = self.dispatch_request()
  File "/home/ubuntu/.local/lib/python2.7/site-packages/flask/app.py", line 1791, in dispatch_request
    return self.view_functions[rule.endpoint](**req.view_args)
  File "/home/ubuntu/api_server/api_server.py", line 106, in get_tasks
    PPTable = getPollsProspect()
  File "/home/ubuntu/.local/lib/python2.7/site-packages/statsd/client.py", line 37, in _wrapped
    return_value = f(*args, **kwargs)
  File "/home/ubuntu/api_server/api_server.py", line 83, in getPollsProspect
    results = q.execute()
  File "/home/ubuntu/.local/lib/python2.7/site-packages/sqlalchemy/sql/base.py", line 386, in execute
    return e._execute_clauseelement(self, multiparams, params)
  File "/home/ubuntu/.local/lib/python2.7/site-packages/sqlalchemy/engine/base.py", line 1998, in _execute_clauseelement
    return connection._execute_clauseelement(elem, multiparams, params)
  File "/home/ubuntu/.local/lib/python2.7/site-packages/sqlalchemy/engine/base.py", line 1010, in _execute_clauseelement
    compiled_sql, distilled_params
  File "/home/ubuntu/.local/lib/python2.7/site-packages/sqlalchemy/engine/base.py", line 1146, in _execute_context
    context)
  File "/home/ubuntu/.local/lib/python2.7/site-packages/sqlalchemy/engine/base.py", line 1341, in _handle_dbapi_exception
    exc_info
  File "/home/ubuntu/.local/lib/python2.7/site-packages/sqlalchemy/util/compat.py", line 200, in raise_from_cause
    reraise(type(exception), exception, tb=exc_tb)
  File "/home/ubuntu/.local/lib/python2.7/site-packages/sqlalchemy/engine/base.py", line 1139, in _execute_context
    context)
  File "/home/ubuntu/.local/lib/python2.7/site-packages/sqlalchemy/engine/default.py", line 450, in do_execute
    cursor.execute(statement, parameters)
  File "/home/ubuntu/.local/lib/python2.7/site-packages/MySQLdb/cursors.py", line 205, in execute
    self.errorhandler(self, exc, value)
  File "/home/ubuntu/.local/lib/python2.7/site-packages/MySQLdb/connections.py", line 36, in defaulterrorhandler
    raise errorclass, errorvalue
OperationalError: (_mysql_exceptions.OperationalError) (2013, 'Lost connection to MySQL server during query') [SQL: u'SELECT polls_prospect.id, polls_prospect.firstname, polls_prospect.lastname, polls_prospect.email \nFROM polls_prospect']
Traceback (most recent call last):
  File "/home/ubuntu/.local/lib/python2.7/site-packages/flask/app.py", line 2301, in __call__
    return self.wsgi_app(environ, start_response)
  File "/home/ubuntu/.local/lib/python2.7/site-packages/flask/app.py", line 2287, in wsgi_app
    response = self.handle_exception(e)
  File "/home/ubuntu/.local/lib/python2.7/site-packages/flask/app.py", line 1733, in handle_exception
    reraise(exc_type, exc_value, tb)
  File "/home/ubuntu/.local/lib/python2.7/site-packages/flask/app.py", line 2284, in wsgi_app
    response = self.full_dispatch_request()
  File "/home/ubuntu/.local/lib/python2.7/site-packages/flask/app.py", line 1807, in full_dispatch_request
    rv = self.handle_user_exception(e)
  File "/home/ubuntu/.local/lib/python2.7/site-packages/flask/app.py", line 1710, in handle_user_exception
    reraise(exc_type, exc_value, tb)
  File "/home/ubuntu/.local/lib/python2.7/site-packages/flask/app.py", line 1805, in full_dispatch_request
    rv = self.dispatch_request()
  File "/home/ubuntu/.local/lib/python2.7/site-packages/flask/app.py", line 1791, in dispatch_request
    return self.view_functions[rule.endpoint](**req.view_args)
  File "/home/ubuntu/api_server/api_server.py", line 106, in get_tasks
    PPTable = getPollsProspect()
  File "/home/ubuntu/.local/lib/python2.7/site-packages/statsd/client.py", line 37, in _wrapped
    return_value = f(*args, **kwargs)
  File "/home/ubuntu/api_server/api_server.py", line 83, in getPollsProspect
    results = q.execute()
  File "/home/ubuntu/.local/lib/python2.7/site-packages/sqlalchemy/sql/base.py", line 386, in execute
    return e._execute_clauseelement(self, multiparams, params)
  File "/home/ubuntu/.local/lib/python2.7/site-packages/sqlalchemy/engine/base.py", line 1998, in _execute_clauseelement
    return connection._execute_clauseelement(elem, multiparams, params)
  File "/home/ubuntu/.local/lib/python2.7/site-packages/sqlalchemy/engine/base.py", line 1010, in _execute_clauseelement
    compiled_sql, distilled_params
  File "/home/ubuntu/.local/lib/python2.7/site-packages/sqlalchemy/engine/base.py", line 1146, in _execute_context
    context)
  File "/home/ubuntu/.local/lib/python2.7/site-packages/sqlalchemy/engine/base.py", line 1341, in _handle_dbapi_exception
    exc_info
  File "/home/ubuntu/.local/lib/python2.7/site-packages/sqlalchemy/util/compat.py", line 200, in raise_from_cause
    reraise(type(exception), exception, tb=exc_tb)
  File "/home/ubuntu/.local/lib/python2.7/site-packages/sqlalchemy/engine/base.py", line 1139, in _execute_context
    context)
  File "/home/ubuntu/.local/lib/python2.7/site-packages/sqlalchemy/engine/default.py", line 450, in do_execute
    cursor.execute(statement, parameters)
  File "/home/ubuntu/.local/lib/python2.7/site-packages/MySQLdb/cursors.py", line 205, in execute
    self.errorhandler(self, exc, value)
  File "/home/ubuntu/.local/lib/python2.7/site-packages/MySQLdb/connections.py", line 36, in defaulterrorhandler
    raise errorclass, errorvalue
OperationalError: (_mysql_exceptions.OperationalError) (2013, 'Lost connection to MySQL server during query') [SQL: u'SELECT polls_prospect.id, polls_prospect.firstname, polls_prospect.lastname, polls_prospect.email \nFROM polls_prospect']
Traceback (most recent call last):
  File "api_server.py", line 10, in <module>
    from statsd import StatsClient
ImportError: No module named statsd
Traceback (most recent call last):
  File "api_server.py", line 10, in <module>
    from statsd import StatsClient
ImportError: No module named statsd
Traceback (most recent call last):
  File "api_server.py", line 46, in <module>
    import requests
ImportError: No module named requests
Traceback (most recent call last):
  File "api_server.py", line 69, in <module>
    eng_to = create_engine(to_conn_str, echo=False)
  File "/home/ubuntu/.local/lib/python2.7/site-packages/sqlalchemy/engine/__init__.py", line 425, in create_engine
    return strategy.create(*args, **kwargs)
  File "/home/ubuntu/.local/lib/python2.7/site-packages/sqlalchemy/engine/strategies.py", line 81, in create
    dbapi = dialect_cls.dbapi(**dbapi_args)
  File "/home/ubuntu/.local/lib/python2.7/site-packages/sqlalchemy/dialects/mysql/mysqldb.py", line 102, in dbapi
    return __import__('MySQLdb')
ImportError: No module named MySQLdb
 * Serving Flask app "api_server" (lazy loading)
 * Environment: production
   WARNING: Do not use the development server in a production environment.
   Use a production WSGI server instead.
 * Debug mode: on
